Workbook

Sheet Sheet1
A1: CATEGORY | B1: GENDER
A2: Action Figures | B2: Accessory
A3: Ankle Length Socks | B3: Accessory
A4: Armour Vests | B4: Accessory
A5: Backpacks | B5: Accessory
A6: Badges | B6: Accessory
A7: Bamboo Toothbrush | B7: Accessory
A8: Biker Masks | B8: Accessory
A9: Bottle Opener Keychain | B9: Accessory
A10: Bucket Hats | B10: Accessory
A11: Caps | B11: Accessory
A12: Cat T-shirts | B12: Accessory
... A480: Women Denim Skirts | B480: Women

Sheet Sheet10
A1: Women T-Shirts | B1: Jersey Tank Tops
A2: Women Relaxed Fit T-Shirts | B2: Women Twisted Tops
A3: Supima Women T-Shirts | B3: Women Rugby Polos
A4: Women Full Sleeve T-Shirts | B4: Women Oversized Crop Tops
A5: Women Boxy Fit Polos | B5: Cropped Tank Tops
A6: Women Tie-up T-Shirts | B6: Women Boxy Fit Polos
A7: Women Full Sleeve T-Shirts | B7: Women Cut-Out Crop Tops
A8: Women Ribbed Henley T-Shirts | B8: Women Tank Tops
A9: Women Capped T-Shirts | B9: Women Cropped Rugby Polos
A10: Women Drop Shoulder T-Shirts | B10: Women Cropped Polos
B11: Women Cropped Tops

Sheet Sheet5
A1: Women Boy Shorts | B1: Women Boy Shorts | G1: sd | H1: asd
A2: Boys Cotton Hooded T-Shirts | B2: Boys Hooded T-Shirts | C2: Boys Topwear | D2: Boys Topwear | E2: Kids | G2: All Day Pants | H2: =VLOOKUP(G2,Sheet1!A:A,1,0) -> All Day Pants
A3: Girls Cotton Oversized Cropped T-Shirts | B3: Girls Oversized Cropped T-Shirts | C3: Girls Topwear | D3: Girls Topwear | E3: Kids | G3: All Weather Hoodies | H3: =VLOOKUP(G3,Sheet1!A:A,1,0) -> All Weather Hoodies
A4: Boys Cotton Hooded Vests | B4: Boys Hooded Vests | C4: Boys Topwear | D4: Boys Topwear | E4: Kids | G4: Backpacks | H4: =VLOOKUP(G4,Sheet1!A:A,1,0) -> Backpacks
A5: Boys Cotton Jackets | B5: Boys Jackets | C5: Boys Topwear | D5: Boys Topwear | E5: Kids | G5: Beach Shorts | H5: =VLOOKUP(G5,Sheet1!A:A,1,0) -> Beach Shorts
A6: Women Holiday Shirts | B6: Women Holiday Shirts | G6: Bomber Neck Polos | H6: =VLOOKUP(G6,Sheet1!A:A,1,0) -> Bomber Neck Polos
A7: Men Parachute Pants | B7: Men Parachute Pants | G7: Boxer Shorts | H7: =VLOOKUP(G7,Sheet1!A:A,1,0) -> Boxer Shorts
A8: Oversized Pullovers | B8: Oversized Pullovers | G8: Boyfriend T-Shirts | H8: =VLOOKUP(G8,Sheet1!A:A,1,0) -> Boyfriend T-Shirts
A9: Varsity Jacket | B9: Varsity Jacket | G9: Boys Cotton Cargo Joggers | H9: =VLOOKUP(G9,Sheet1!A:A,1,0) -> Boys Cotton Cargo Joggers
A10: Girls Cotton Sweaters | B10: Girls Sweaters | C10: #N/A | D10: #N/A | E10: #N/A | G10: Boys Cotton Co-ord Sets | H10: =VLOOKUP(G10,Sheet1!A:A,1,0) -> Boys Cotton Co-ord Sets
A11: Girls Cotton Jackets | B11: Girls Jackets | C11: #N/A | D11: #N/A | E11: #N/A | G11: Boys Cotton Full Sleeve T-Shirts | H11: =VLOOKUP(G11,Sheet1!A:A,1,0) -> Boys Cotton Full Sleeve T-Shirts
A12: Boys Cotton Hooded Utility Jacket | B12: Boys Hooded Utility Jacket | C12: #N/A | D12: #N/A | E12: #N/A | G12: Boys Cotton Hooded T-Shirts | H12: =VLOOKUP(G12,Sheet1!A:A,1,0) -> Boys Cotton Hooded T-Shirts
A13: Boys Puffer Hooded Jacket | B13: Boys Puffer Hooded Jacket | G13: Boys Cotton Hooded Vests | H13: =VLOOKUP(G13,Sheet1!A:A,1,0) -> Boys Cotton Hooded Vests
A14: Boys Cotton Sweaters | B14: Boys Sweaters | C14: #N/A | D14: #N/A | E14: #N/A | G14: Boys Cotton Hoodies | H14: =VLOOKUP(G14,Sheet1!A:A,1,0) -> Boys Cotton Hoodies
A15: Women Oversized Varsity Jacket | B15: Women Oversized Varsity Jacket | G15: Boys Cotton Jackets | H15: =VLOOKUP(G15,Sheet1!A:A,1,0) -> Boys Cotton Jackets
A16: Bomber Jackets | B16: Bomber Jackets | G16: Boys Cotton Joggers | H16: =VLOOKUP(G16,Sheet1!A:A,1,0) -> Boys Cotton Joggers
A17: Racer Jacket | B17: Racer Jacket | G17: Boys Cotton Oversized Hooded T-Shirts | H17: =VLOOKUP(G17,Sheet1!A:A,1,0) -> Boys Cotton Oversized Hooded T-Shirts
A18: Oversized Puffer Jackets | B18: Oversized Puffer Jackets | G18: Boys Cotton Oversized T-Shirts | H18: =VLOOKUP(G18,Sheet1!A:A,1,0) -> Boys Cotton Oversized T-Shirts
A19: Women Vest Sweaters | B19: Women Vest Sweaters | G19: Boys Cotton Polo T-Shirts | H19: =VLOOKUP(G19,Sheet1!A:A,1,0) -> Boys Cotton Polo T-Shirts
A20: Women Oversized Sweaters | B20: Women Oversized Sweaters | G20: Boys Cotton Shirts | H20: =VLOOKUP(G20,Sheet1!A:A,1,0) -> Boys Cotton Shirts
A21: Boys Cotton Varsity Hooded Jacket | B21: Boys Varsity Hooded Jacket | C21: #N/A | D21: #N/A | E21: #N/A | G21: Boys Cotton Shorts | H21: =VLOOKUP(G21,Sheet1!A:A,1,0) -> Boys Cotton Shorts
A22: Boys Cotton Zipper Hooded Jacket | B22: Boys Zipper Hooded Jacket | C22: #N/A | D22: #N/A | E22: #N/A | G22: Boys Cotton Sweatshirts | H22: =VLOOKUP(G22,Sheet1!A:A,1,0) -> Boys Cotton Sweatshirts
A23: Boys Cotton Zipper Jacket | B23: Boys Zipper Jacket | C23: #N/A | D23: #N/A | E23: #N/A | G23: Boys Cotton T-Shirts | H23: =VLOOKUP(G23,Sheet1!A:A,1,0) -> Boys Cotton T-Shirts
A24: Boys Cotton Varsity Jacket | B24: Boys Varsity Jacket | C24: #N/A | D24: #N/A | E24: #N/A | G24: Boys Puffer Jackets | H24: =VLOOKUP(G24,Sheet1!A:A,1,0) -> Boys Puffer Jackets
A25: Girls Cotton Dresses | B25: Girls Dresses | C25: Girls Topwear | D25: Girls Topwear | E25: Kids | G25: Briefs Underwear | H25: =VLOOKUP(G25,Sheet1!A:A,1,0) -> Briefs Underwear
A26: Men Slim Fit Jeans | B26: Men Slim Fit Jeans | G26: Bucket Hats | H26: =VLOOKUP(G26,Sheet1!A:A,1,0) -> Bucket Hats
A27: Girls Cotton Tank Tops | B27: Girls Tank Tops | C27: Girls Topwear | D27: Girls Topwear | E27: Kids | G27: Caps | H27: =VLOOKUP(G27,Sheet1!A:A,1,0) -> Caps
A28: Girls Cotton Jeans | B28: Girls Jeans | C28: Girls Bottomwear | D28: Girls Bottomwear | E28: Kids | G28: Chino Pants | H28: =VLOOKUP(G28,Sheet1!A:A,1,0) -> Chino Pants
A29: Boys Cotton Jeans | B29: Boys Jeans | C29: #N/A | D29: #N/A | E29: #N/A | G29: Corporate T-Shirts | H29: =VLOOKUP(G29,Sheet1!A:A,1,0) -> Corporate T-Shirts
A30: Boys Cotton Cargo Jeans | B30: Boys Cargo Jeans | C30: #N/A | D30: #N/A | E30: #N/A | G30: Cotton Linen Shirts | H30: =VLOOKUP(G30,Sheet1!A:A,1,0) -> Cotton Linen Shirts
A31: Girls Cotton Polo Dresses | B31: Girls Polo Dresses | C31: Girls Topwear | D31: Girls Topwear | E31: Kids | G31: Cropped Shirts | H31: =VLOOKUP(G31,Sheet1!A:A,1,0) -> Cropped Shirts
A32: Girls Cotton Cropped Rugby Polos | B32: Girls Cropped Rugby Polos | C32: Women Polos | D32: Women Polos | E32: Kids | G32: Cropped Tank Tops | H32: =VLOOKUP(G32,Sheet1!A:A,1,0) -> Cropped Tank Tops
A33: Boys Cotton Sleeveless T-Shirts | B33: Boys Sleeveless T-Shirts | C33: Boys Topwear | D33: Boys Topwear | E33: Kids | G33: Denim Dresses | H33: =VLOOKUP(G33,Sheet1!A:A,1,0) -> Denim Dresses
A34: Boys Cotton Oversized Hooded T-Shirts | B34: Boys Oversized Hooded T-Shirts | C34: #N/A | D34: #N/A | E34: #N/A | G34: Denim Jackets | H34: =VLOOKUP(G34,Sheet1!A:A,1,0) -> Denim Jackets
G35: Denim Joggers | H35: =VLOOKUP(G35,Sheet1!A:A,1,0) -> Denim Joggers
G36: Denim Shirts | H36: =VLOOKUP(G36,Sheet1!A:A,1,0) -> Denim Shirts
G37: Drop Cut T-Shirts | H37: =VLOOKUP(G37,Sheet1!A:A,1,0) -> Drop Cut T-Shirts
G38: Drop Shoulder Pocket Dresses | H38: =VLOOKUP(G38,Sheet1!A:A,1,0) -> Drop Shoulder Pocket Dresses
G39: Easy Fit Full Sleeve T-Shirts | H39: =VLOOKUP(G39,Sheet1!A:A,1,0) -> Easy Fit Full Sleeve T-Shirts
G40: Easy Fit T-Shirts | H40: =VLOOKUP(G40,Sheet1!A:A,1,0) -> Easy Fit T-Shirts
...
